Workbook

Sheet Lisez-moi
A1: IA Factor / AgentIA — suivi financier
A2: Associés : Daouda Danso (technique), Régis Pepin (chef de projet). Créé le 04/10/2026 à partir de ia-factor-admin/finances.
A4: Onglets
A5: Paramètres : scénario actif (pessimiste / central / optimiste), prix des offres, taux, hypothèses de croissance.
A6: Coûts : tableau des coûts (frais fixes mensuels, annuels, ponctuels) avec équivalents mensuel et annuel, et qui paie.
A7: Avances : dépenses payées personnellement par un associé (futur compte courant d'associé), à rembourser.
A8: Projection : 24 mois (oct. 2026 → sept. 2028) : clients, chiffre d'affaires, charges, résultat, apports, trésorerie.
A9: Synthèse : chiffres clés par année, seuil de rentabilité, besoin de trésorerie.
A10: Bilan : compte de résultat et bilan simplifiés de fin d'année 1 et 2 (vue de gestion).
A11: Suivi réel : chaque mois, saisir le réel et comparer à la projection.
A13: Mode d'emploi
A14: Cellules sur fond bleu clair, texte bleu = valeurs à saisir ou à ajuster. Les autres cellules sont des formules : ne pas les écraser.
... A24: Montants en dollars convertis avec le taux de Paramètres (1 $ = 0,92 € par défaut).

Sheet Synthèse
B1: Synthèse
B2: ="Scénario : "&'Paramètres'!C3
B4: Indicateur | C4: Année 1 | D4: Année 2 | E4: Total 24 mois | F4: Lecture
B5: Chiffre d'affaires — installations | C5: =SUMIFS('Projection'!$J$5:$J$28,'Projection'!$C$5:$C$28,"Année 1") | D5: =SUMIFS('Projection'!$J$5:$J$28,'Projection'!$C$5:$C$28,"Année 2") | E5: =C5+D5
B6: Chiffre d'affaires — abonnements | C6: =SUMIFS('Projection'!$K$5:$K$28,'Projection'!$C$5:$C$28,"Année 1") | D6: =SUMIFS('Projection'!$K$5:$K$28,'Projection'!$C$5:$C$28,"Année 2") | E6: =C6+D6
B7: Chiffre d'affaires total | C7: =SUMIFS('Projection'!$L$5:$L$28,'Projection'!$C$5:$C$28,"Année 1") | D7: =SUMIFS('Projection'!$L$5:$L$28,'Projection'!$C$5:$C$28,"Année 2") | E7: =C7+D7
B8: Coûts variables (IA par client…) | C8: =SUMIFS('Projection'!$M$5:$M$28,'Projection'!$C$5:$C$28,"Année 1") | D8: =SUMIFS('Projection'!$M$5:$M$28,'Projection'!$C$5:$C$28,"Année 2") | E8: =C8+D8
B9: Frais Stripe | C9: =SUMIFS('Projection'!$N$5:$N$28,'Projection'!$C$5:$C$28,"Année 1") | D9: =SUMIFS('Projection'!$N$5:$N$28,'Projection'!$C$5:$C$28,"Année 2") | E9: =C9+D9
B10: Frais fixes | C10: =SUMIFS('Projection'!$O$5:$O$28,'Projection'!$C$5:$C$28,"Année 1") | D10: =SUMIFS('Projection'!$O$5:$O$28,'Projection'!$C$5:$C$28,"Année 2") | E10: =C10+D10
B11: Dépenses ponctuelles (démarches, kit…) | C11: =SUMIFS('Projection'!$P$5:$P$28,'Projection'!$C$5:$C$28,"Année 1") | D11: =SUMIFS('Projection'!$P$5:$P$28,'Projection'!$C$5:$C$28,"Année 2") | E11: =C11+D11
B12: Cotisations sociales et impôt | C12: =SUMIFS('Projection'!$Q$5:$Q$28,'Projection'!$C$5:$C$28,"Année 1") | D12: =SUMIFS('Projection'!$Q$5:$Q$28,'Projection'!$C$5:$C$28,"Année 2") | E12: =C12+D12
B13: Résultat | C13: =SUMIFS('Projection'!$R$5:$R$28,'Projection'!$C$5:$C$28,"Année 1") | D13: =SUMIFS('Projection'!$R$5:$R$28,'Projection'!$C$5:$C$28,"Année 2") | E13: =C13+D13
B14: Apports des associés | C14: =SUMIFS('Projection'!$S$5:$S$28,'Projection'!$C$5:$C$28,"Année 1") | D14: =SUMIFS('Projection'!$S$5:$S$28,'Projection'!$C$5:$C$28,"Année 2") | E14: =C14+D14
B16: Clients Entreprise actifs en fin d'année | C16: ='Projection'!E16 | D16: ='Projection'!E28
B17: Revenu mensuel récurrent en fin d'année | C17: ='Projection'!K16 | D17: ='Projection'!K28 | F17: Abonnements du dernier mois
B18: Trésorerie en fin d'année | C18: ='Projection'!T16 | D18: ='Projection'!T28 | F18: Rouge = à financer par des apports
B19: Besoin de trésorerie maximum (creux) | C19: =MAX(0,-MIN('Projection'!T5:T16)) | D19: =MAX(0,-MIN('Projection'!T5:T28)) | F19: Apport minimum à prévoir
B20: Marge par client Entreprise (€/mois) | C20: ='Paramètres'!$D$19-'Paramètres'!$C$11-'Paramètres'!$D$19*'Paramètres'!$C$24-'Paramètres'!$C$25-'Paramètres'!$D$19*('Paramètres'!$C$26+'Paramètres'!$C$27) | F20: Abonnement − coût variable − Stripe − cotisations
B21: Frais fixes actuels (€/mois) | C21: ='Coûts'!$C$65 | F21: Onglet Coûts, lignes incluses
B22: Seuil de rentabilité (clients Entreprise) | C22: =ROUNDUP(C21/C20,0) | F22: Clients nécessaires pour couvrir les frais fixes
B23: CA annuel vs seuil de franchise de TVA | C23: =C7/'Paramètres'!$C$29 | D23: =D7/'Paramètres'!$C$29 | F23: Au-delà de 100 % : TVA à facturer

Sheet Paramètres
B1: Paramètres et hypothèses
B3: Scénario actif | C3: Central
B4: Index du scénario | C4: =MATCH(C3,D7:F7,0)
B5: Taux de change (1 $ en €) | C5: 0.92 | G5: À ajuster au cours du jour
B7: Hypothèse de croissance | C7: Valeur retenue | D7: Pessimiste | E7: Central | F7: Optimiste | G7: Remarque
B8: Mois du 1er client Entreprise payant (M1 = oct. 2026) | C8: =INDEX(D8:F8,$C$4) | D8: 4 | E8: 3 | F8: 3 | G8: Oct.–nov. 2026 : pilotes gratuits
B9: Nouveaux clients Entreprise par mois | C9: =INDEX(D9:F9,$C$4) | D9: 1 | E9: 2 | F9: 4 | G9: Rythme de signature : indicateur porté par Régis
B10: Résiliation mensuelle | C10: =INDEX(D10:F10,$C$4) | D10: 0.04 | E10: 0.02 | F10: 0.01
B11: Coût variable par client Entreprise (€/mois) | C11: =INDEX(D11:F11,$C$4) | D11: 10 | E11: 6 | F11: 4 | G11: IA Claude (mesuré ~0,2 centime/message), rappels
B12: Majoration des coûts fixes (€/mois) | C12: =INDEX(D12:F12,$C$4) | D12: 10 | E12: 0 | F12: 0 | G12: Marge de prudence
B13: Mois de lancement Particulier / AideHandicap | C13: =INDEX(D13:F13,$C$4) | D13: 12 | E13: 9 | F13: 6 | G13: Bots à créer ; offres codées, validation juridique obtenue
B14: Nouveaux utilisateurs Particulier par mois | C14: =INDEX(D14:F14,$C$4) | D14: 0 | E14: 0 | F14: 0 | G14: À estimer avant lancement
B15: Nouveaux utilisateurs AideHandicap par mois | C15: =INDEX(D15:F15,$C$4) | D15: 0 | E15: 0 | F15: 0 | G15: À estimer avant lancement
B18: Offre | C18: Installation (€) | D18: Abonnement (€/mois) | E18: Coût variable (€/mois) | G18: Remarque
B19: Entreprise (TPE/PME) | C19: 199 | D19: 30 | E19: =$C$11 | G19: Pilotes gratuits ; tarif standard ensuite
B20: Particulier | C20: 149 | D20: 20 | E20: 3 | G20: Prix de la présentation initiale, à confirmer
B21: AideHandicap | C21: 149 | D21: 20 | E21: 3 | G21: Prix de la présentation initiale, à confirmer
B23: Taux et dates | C23: Valeur | G23: Remarque
B24: Frais Stripe (% du paiement) | C24: 0.015 | G24: Cartes UE, à vérifier
B25: Frais Stripe fixes par paiement (€) | C25: 0.25 | G25: À vérifier
B26: Cotisations sociales micro-entreprise (% du CA) | C26: 0.212 | G26: Prestations de services : à vérifier sur urssaf.fr
B27: Versement libératoire de l'impôt (% du CA, option) | C27: 0 | G27: 1,7 % si l'option est prise ; 0 sinon
B28: Début de la projection | C28: 46296 | G28: M1
B29: Seuil de franchise de TVA (services, €/an) | C29: 37500 | G29: À vérifier : au-delà, facturer la TVA

Sheet Coûts
A1: Tableau des coûts
A2: Type : Mensuel, Annuel, Ponctuel (une fois, au mois de la date de début) ou Variable (par client, voir Paramètres). Inclus = Non : ignoré dans les totaux et la projection.
A4: Catégorie | B4: Poste | C4: Fournisseur | D4: Type | E4: Montant | F4: Devise | G4: Montant (€) | H4: Équiv. mensuel (€) | I4: Équiv. annuel (€) | J4: Inclus | K4: Début | L4: Fin | M4: Payé par | N4: Statut | O4: Remarque
A5: Infrastructure | B5: VPS KVM 2 (2 vCPU, 8 Go) | C5: Hostinger | D5: Mensuel | E5: 24.49 | F5: $ | G5: =IF(E5="","",IF(F5="$",E5*'Paramètres'!$C$5,E5)) | H5: =IF(J5<>"Oui",0,IF(D5="Mensuel",G5,IF(D5="Annuel",G5/12,0))) | I5: =IF(J5<>"Oui",0,IF(D5="Ponctuel",G5,H5*12)) | J5: Oui | K5: 46291 | M5: Daouda | N5: Engagé | O5: Prélevé le 26 de chaque mois ; comparer avec un engagement 12/24 mois
A6: Infrastructure | B6: Domaine ia-factor.fr | C6: Hostinger | D6: Annuel | E6: 12.99 | F6: $ | G6: =IF(E6="","",IF(F6="$",E6*'Paramètres'!$C$5,E6)) | H6: =IF(J6<>"Oui",0,IF(D6="Mensuel",G6,IF(D6="Annuel",G6/12,0))) | I6: =IF(J6<>"Oui",0,IF(D6="Ponctuel",G6,H6*12)) | J6: Oui | K6: 46291 | M6: Daouda | N6: Payé | O6: Renouvellement automatique le 30/08/2027 ; montant 1re année à renseigner
A7: Infrastructure | B7: Domaine ia-factor.com | C7: IONOS | D7: Annuel | E7: 10 | F7: € | G7: =IF(E7="","",IF(F7="$",E7*'Paramètres'!$C$5,E7)) | H7: =IF(J7<>"Oui",0,IF(D7="Mensuel",G7,IF(D7="Annuel",G7/12,0))) | I7: =IF(J7<>"Oui",0,IF(D7="Ponctuel",G7,H7*12)) | J7: Oui | K7: 46291 | M7: Régis | N7: Payé | O7: Renouvellement automatique le 26/09/2027 (tarif de renouvellement à renseigner)
A8: Infrastructure | B8: Domaine ai-team.fr (abandonné) | C8: Hostinger | D8: Ponctuel | E8: 0 | F8: € | G8: =IF(E8="","",IF(F8="$",E8*'Paramètres'!$C$5,E8)) | H8: =IF(J8<>"Oui",0,IF(D8="Mensuel",G8,IF(D8="Annuel",G8/12,0))) | I8: =IF(J8<>"Oui",0,IF(D8="Ponctuel",G8,H8*12)) | J8: Oui | K8: 46291 | M8: Daouda | N8: À renseigner | O8: Non renouvelé
A9: Infrastructure | B9: E-mail contact@ia-factor.fr | C9: À choisir | D9: Mensuel | E9: 2 | F9: € | G9: =IF(E9="","",IF(F9="$",E9*'Paramètres'!$C$5,E9)) | H9: =IF(J9<>"Oui",0,IF(D9="Mensuel",G9,IF(D9="Annuel",G9/12,0))) | I9: =IF(J9<>"Oui",0,IF(D9="Ponctuel",G9,H9*12)) | J9: Oui | K9: 46327 | M9: À définir | N9: Estimation | O9: Pas encore créé
A10: Infrastructure | B10: Sauvegardes (Backblaze B2) | C10: Backblaze | D10: Mensuel | E10: 0 | F10: € | G10: =IF(E10="","",IF(F10="$",E10*'Paramètres'!$C$5,E10)) | H10: =IF(J10<>"Oui",0,IF(D10="Mensuel",G10,IF(D10="Annuel",G10/12,0))) | I10: =IF(J10<>"Oui",0,IF(D10="Ponctuel",G10,H10*12)) | J10: Oui | K10: 46327 | N10: Estimation | O10: Gratuit jusqu'à 10 Go
A11: IA | B11: API Claude — démo publique | C11: Anthropic | D11: Mensuel | E11: 3 | F11: € | G11: =IF(E11="","",IF(F11="$",E11*'Paramètres'!$C$5,E11)) | H11: =IF(J11<>"Oui",0,IF(D11="Mensuel",G11,IF(D11="Annuel",G11/12,0))) | I11: =IF(J11<>"Oui",0,IF(D11="Ponctuel",G11,H11*12)) | J11: Oui | K11: 46296 | M11: Daouda | N11: Estimation | O11: Plafond technique 0,30 $/jour (~8 €/mois max)
A12: IA | B12: API Claude — crédits prépayés initiaux | C12: Anthropic | D12: Ponctuel | E12: 6 | F12: $ | G12: =IF(E12="","",IF(F12="$",E12*'Paramètres'!$C$5,E12)) | H12: =IF(J12<>"Oui",0,IF(D12="Mensuel",G12,IF(D12="Annuel",G12/12,0))) | I12: =IF(J12<>"Oui",0,IF(D12="Ponctuel",G12,H12*12)) | J12: Oui | K12: 46292 | M12: Daouda | N12: Payé | O12: 5 $ + 1 $ de taxes, expirent le 27/09/2027
A13: IA | B13: API Claude — agent des clients | C13: Anthropic | D13: Variable | E13: 0 | F13: € | G13: =IF(E13="","",IF(F13="$",E13*'Paramètres'!$C$5,E13)) | H13: =IF(J13<>"Oui",0,IF(D13="Mensuel",G13,IF(D13="Annuel",G13/12,0))) | I13: =IF(J13<>"Oui",0,IF(D13="Ponctuel",G13,H13*12)) | J13: Oui | M13: Société | N13: Estimation | O13: Par client : voir Paramètres (coût variable)
A14: IA | B14: Abonnement Claude (Claude Code, développement) | C14: Anthropic | D14: Mensuel | E14: 20 | F14: € | G14: =IF(E14="","",IF(F14="$",E14*'Paramètres'!$C$5,E14)) | H14: =IF(J14<>"Oui",0,IF(D14="Mensuel",G14,IF(D14="Annuel",G14/12,0))) | I14: =IF(J14<>"Oui",0,IF(D14="Ponctuel",G14,H14*12)) | J14: Oui | K14: 46266 | M14: Daouda | N14: À renseigner | O14: Pro ~20 $/mois, Max 100–200 $/mois ; à décider : dépense du projet ou personnelle
A15: Démarches | B15: Création micro-entreprise | C15: URSSAF / guichet unique | D15: Ponctuel | E15: 0 | F15: € | G15: =IF(E15="","",IF(F15="$",E15*'Paramètres'!$C$5,E15)) | H15: =IF(J15<>"Oui",0,IF(D15="Mensuel",G15,IF(D15="Annuel",G15/12,0))) | I15: =IF(J15<>"Oui",0,IF(D15="Ponctuel",G15,H15*12)) | J15: Oui | K15: 46327 | N15: Estimation | O15: Gratuit
A16: Démarches | B16: Création société (SAS/SASU, annonce légale) | C16: Guichet unique | D16: Ponctuel | E16: 400 | F16: € | G16: =IF(E16="","",IF(F16="$",E16*'Paramètres'!$C$5,E16)) | H16: =IF(J16<>"Oui",0,IF(D16="Mensuel",G16,IF(D16="Annuel",G16/12,0))) | I16: =IF(J16<>"Oui",0,IF(D16="Ponctuel",G16,H16*12)) | J16: Non | K16: 46327 | N16: Estimation | O16: Alternative à la micro-entreprise : 300–500 €
A17: Démarches | B17: Dépôt de marque INPI (1 classe) | C17: INPI | D17: Ponctuel | E17: 190 | F17: € | G17: =IF(E17="","",IF(F17="$",E17*'Paramètres'!$C$5,E17)) | H17: =IF(J17<>"Oui",0,IF(D17="Mensuel",G17,IF(D17="Annuel",G17/12,0))) | I17: =IF(J17<>"Oui",0,IF(D17="Ponctuel",G17,H17*12)) | J17: Oui | K17: 46327 | M17: À définir | N17: Estimation | O17: À vérifier sur inpi.fr
A18: Démarches | B18: Relecture juridique (CGV, confidentialité, contrat de sous-traitance) | C18: Juriste / DPO | D18: Ponctuel | E18: 800 | F18: € | G18: =IF(E18="","",IF(F18="$",E18*'Paramètres'!$C$5,E18)) | H18: =IF(J18<>"Oui",0,IF(D18="Mensuel",G18,IF(D18="Annuel",G18/12,0))) | I18: =IF(J18<>"Oui",0,IF(D18="Ponctuel",G18,H18*12)) | J18: Oui | K18: 46357 | M18: À définir | N18: Estimation | O18: 500–1 000 €
A19: Démarches | B19: Assurance RC Pro | C19: À choisir | D19: Annuel | E19: 240 | F19: € | G19: =IF(E19="","",IF(F19="$",E19*'Paramètres'!$C$5,E19)) | H19: =IF(J19<>"Oui",0,IF(D19="Mensuel",G19,IF(D19="Annuel",G19/12,0))) | I19: =IF(J19<>"Oui",0,IF(D19="Ponctuel",G19,H19*12)) | J19: Oui | K19: 46357 | M19: Société | N19: Estimation | O19: 150–400 €/an
A20: Démarches | B20: Banque professionnelle | C20: À choisir | D20: Mensuel | E20: 5 | F20: € | G20: =IF(E20="","",IF(F20="$",E20*'Paramètres'!$C$5,E20)) | H20: =IF(J20<>"Oui",0,IF(D20="Mensuel",G20,IF(D20="Annuel",G20/12,0))) | I20: =IF(J20<>"Oui",0,IF(D20="Ponctuel",G20,H20*12)) | J20: Oui | K20: 46357 | M20: Société | N20: Estimation | O20: 0–10 €/mois
A21: Démarches | B21: Expert-comptable | C21: À choisir | D21: Mensuel | E21: 120 | F21: € | G21: =IF(E21="","",IF(F21="$",E21*'Paramètres'!$C$5,E21)) | H21: =IF(J21<>"Oui",0,IF(D21="Mensuel",G21,IF(D21="Annuel",G21/12,0))) | I21: =IF(J21<>"Oui",0,IF(D21="Ponctuel",G21,H21*12)) | J21: Non | K21: 46388 | M21: Société | N21: Estimation | O21: Seulement en société : 80–150 €/mois
A22: Commercial | B22: Community manager (freelance) | C22: À choisir | D22: Mensuel | E22: 400 | F22: € | G22: =IF(E22="","",IF(F22="$",E22*'Paramètres'!$C$5,E22)) | H22: =IF(J22<>"Oui",0,IF(D22="Mensuel",G22,IF(D22="Annuel",G22/12,0))) | I22: =IF(J22<>"Oui",0,IF(D22="Ponctuel",G22,H22*12)) | J22: Non | K22: 46447 | M22: Société | N22: Estimation | O22: Réseaux sociaux, contenus : 300–600 €/mois selon volume
A23: Commercial | B23: Kit commerçant (QR codes, affichettes imprimées) | C23: Imprimeur | D23: Ponctuel | E23: 50 | F23: € | G23: =IF(E23="","",IF(F23="$",E23*'Paramètres'!$C$5,E23)) | H23: =IF(J23<>"Oui",0,IF(D23="Mensuel",G23,IF(D23="Annuel",G23/12,0))) | I23: =IF(J23<>"Oui",0,IF(D23="Ponctuel",G23,H23*12)) | J23: Oui | K23: 46357 | M23: À définir | N23: Estimation
A24: Commercial | B24: Publicité en ligne | C24: Google / Meta | D24: Mensuel | E24: 100 | F24: € | G24: =IF(E24="","",IF(F24="$",E24*'Paramètres'!$C$5,E24)) | H24: =IF(J24<>"Oui",0,IF(D24="Mensuel",G24,IF(D24="Annuel",G24/12,0))) | I24: =IF(J24<>"Oui",0,IF(D24="Ponctuel",G24,H24*12)) | J24: Non | K24: 46447 | M24: Société | N24: Estimation | O24: Optionnel
A25: Commercial | B25: Déplacements de prospection | D25: Mensuel | E25: 30 | F25: € | G25: =IF(E25="","",IF(F25="$",E25*'Paramètres'!$C$5,E25)) | H25: =IF(J25<>"Oui",0,IF(D25="Mensuel",G25,IF(D25="Annuel",G25/12,0))) | I25: =IF(J25<>"Oui",0,IF(D25="Ponctuel",G25,H25*12)) | J25: Non | K25: 46327 | M25: Régis | N25: Estimation | O25: Optionnel
A26: Paiement | B26: Frais Stripe | C26: Stripe | D26: Variable | E26: 0 | F26: € | G26: =IF(E26="","",IF(F26="$",E26*'Paramètres'!$C$5,E26)) | H26: =IF(J26<>"Oui",0,IF(D26="Mensuel",G26,IF(D26="Annuel",G26/12,0))) | I26: =IF(J26<>"Oui",0,IF(D26="Ponctuel",G26,H26*12)) | J26: Oui | M26: Société | N26: Estimation | O26: Voir Paramètres : % + fixe par paiement
A27: Paiement | B27: Messages WhatsApp (V2) | C27: Meta | D27: Variable | E27: 0 | F27: € | G27: =IF(E27="","",IF(F27="$",E27*'Paramètres'!$C$5,E27)) | H27: =IF(J27<>"Oui",0,IF(D27="Mensuel",G27,IF(D27="Annuel",G27/12,0))) | I27: =IF(J27<>"Oui",0,IF(D27="Ponctuel",G27,H27*12)) | J27: Non | M27: Société | N27: Estimation | O27: V2 seulement ; V1 sur Telegram : gratuit
G28: =IF(E28="","",IF(F28="$",E28*'Paramètres'!$C$5,E28)) | H28: =IF(J28<>"Oui",0,IF(D28="Mensuel",G28,IF(D28="Annuel",G28/12,0))) | I28: =IF(J28<>"Oui",0,IF(D28="Ponctuel",G28,H28*12))
G29: =IF(E29="","",IF(F29="$",E29*'Paramètres'!$C$5,E29)) | H29: =IF(J29<>"Oui",0,IF(D29="Mensuel",G29,IF(D29="Annuel",G29/12,0))) | I29: =IF(J29<>"Oui",0,IF(D29="Ponctuel",G29,H29*12))
G30: =IF(E30="","",IF(F30="$",E30*'Paramètres'!$C$5,E30)) | H30: =IF(J30<>"Oui",0,IF(D30="Mensuel",G30,IF(D30="Annuel",G30/12,0))) | I30: =IF(J30<>"Oui",0,IF(D30="Ponctuel",G30,H30*12))
G31: =IF(E31="","",IF(F31="$",E31*'Paramètres'!$C$5,E31)) | H31: =IF(J31<>"Oui",0,IF(D31="Mensuel",G31,IF(D31="Annuel",G31/12,0))) | I31: =IF(J31<>"Oui",0,IF(D31="Ponctuel",G31,H31*12))
G32: =IF(E32="","",IF(F32="$",E32*'Paramètres'!$C$5,E32)) | H32: =IF(J32<>"Oui",0,IF(D32="Mensuel",G32,IF(D32="Annuel",G32/12,0))) | I32: =IF(J32<>"Oui",0,IF(D32="Ponctuel",G32,H32*12))
G33: =IF(E33="","",IF(F33="$",E33*'Paramètres'!$C$5,E33)) | H33: =IF(J33<>"Oui",0,IF(D33="Mensuel",G33,IF(D33="Annuel",G33/12,0))) | I33: =IF(J33<>"Oui",0,IF(D33="Ponctuel",G33,H33*12))
G34: =IF(E34="","",IF(F34="$",E34*'Paramètres'!$C$5,E34)) | H34: =IF(J34<>"Oui",0,IF(D34="Mensuel",G34,IF(D34="Annuel",G34/12,0))) | I34: =IF(J34<>"Oui",0,IF(D34="Ponctuel",G34,H34*12))
G35: =IF(E35="","",IF(F35="$",E35*'Paramètres'!$C$5,E35)) | H35: =IF(J35<>"Oui",0,IF(D35="Mensuel",G35,IF(D35="Annuel",G35/12,0))) | I35: =IF(J35<>"Oui",0,IF(D35="Ponctuel",G35,H35*12))
G36: =IF(E36="","",IF(F36="$",E36*'Paramètres'!$C$5,E36)) | H36: =IF(J36<>"Oui",0,IF(D36="Mensuel",G36,IF(D36="Annuel",G36/12,0))) | I36: =IF(J36<>"Oui",0,IF(D36="Ponctuel",G36,H36*12))
G37: =IF(E37="","",IF(F37="$",E37*'Paramètres'!$C$5,E37)) | H37: =IF(J37<>"Oui",0,IF(D37="Mensuel",G37,IF(D37="Annuel",G37/12,0))) | I37: =IF(J37<>"Oui",0,IF(D37="Ponctuel",G37,H37*12))
G38: =IF(E38="","",IF(F38="$",E38*'Paramètres'!$C$5,E38)) | H38: =IF(J38<>"Oui",0,IF(D38="Mensuel",G38,IF(D38="Annuel",G38/12,0))) | I38: =IF(J38<>"Oui",0,IF(D38="Ponctuel",G38,H38*12))
G39: =IF(E39="","",IF(F39="$",E39*'Paramètres'!$C$5,E39)) | H39: =IF(J39<>"Oui",0,IF(D39="Mensuel",G39,IF(D39="Annuel",G39/12,0))) | I39: =IF(J39<>"Oui",0,IF(D39="Ponctuel",G39,H39*12))
... G60: =IF(E60="","",IF(F60="$",E60*'Paramètres'!$C$5,E60)) | H60: =IF(J60<>"Oui",0,IF(D60="Mensuel",G60,IF(D60="Annuel",G60/12,0))) | I60: =IF(J60<>"Oui",0,IF(D60="Ponctuel",G60,H60*12))
B62: Totaux (lignes Inclus = Oui)
...

Sheet Projection
A1: Projection sur 24 mois
A2: ="Scénario : "&'Paramètres'!C3&" — changer dans Paramètres. Colonne Apports : à saisir (argent mis par les associés)."
A4: N° | B4: Mois | C4: Année | D4: Nouveaux clients Entreprise | E4: Clients Entreprise actifs | F4: Nouveaux Particulier | G4: Actifs Particulier | H4: Nouveaux AideHandicap | I4: Actifs AideHandicap | J4: CA installations | K4: CA abonnements | L4: CA total | M4: Coûts variables | N4: Frais Stripe | O4: Frais fixes | P4: Dépenses ponctuelles | Q4: Cotisations et impôt | R4: Résultat du mois | S4: Apports des associés | T4: Trésorerie fin de mois
A5: 1 | B5: =EDATE('Paramètres'!$C$28,A5-1) | C5: =IF(A5<=12,"Année 1","Année 2") | D5: =IF(A5>='Paramètres'!$C$8,'Paramètres'!$C$9,0) | E5: =D5 | F5: =IF(A5>='Paramètres'!$C$13,'Paramètres'!$C$14,0) | G5: =F5 | H5: =IF(A5>='Paramètres'!$C$13,'Paramètres'!$C$15,0) | I5: =H5 | J5: =D5*'Paramètres'!$C$19+F5*'Paramètres'!$C$20+H5*'Paramètres'!$C$21 | K5: =E5*'Paramètres'!$D$19+G5*'Paramètres'!$D$20+I5*'Paramètres'!$D$21 | L5: =J5+K5 | M5: =E5*'Paramètres'!$C$11+G5*'Paramètres'!$E$20+I5*'Paramètres'!$E$21 | N5: =L5*'Paramètres'!$C$24+(D5+E5+F5+G5+H5+I5)*'Paramètres'!$C$25 | O5: =SUMPRODUCT(('Coûts'!$D$5:$D$60="Mensuel")*('Coûts'!$J$5:$J$60="Oui")*('Coûts'!$K$5:$K$60<=EOMONTH(B5,0))*(('Coûts'!$L$5:$L$60="")+('Coûts'!$L$5:$L$60>=B5)>0)*'Coûts'!$H$5:$H$60)+SUMPRODUCT(('Coûts'!$D$5:$D$60="Annuel")*('Coûts'!$J$5:$J$60="Oui")*('Coûts'!$K$5:$K$60<=EOMONTH(B5,0))*(('Coûts'!$L$5:$L$60="")+('Coûts'!$L$5:$L$60>=B5)>0)*'Coûts'!$H$5:$H$60)+'Paramètres'!$C$12 | P5: =SUMPRODUCT(('Coûts'!$D$5:$D$60="Ponctuel")*('Coûts'!$J$5:$J$60="Oui")*('Coûts'!$K$5:$K$60<=EOMONTH(B5,0))*((('Coûts'!$K$5:$K$60>=B5)+(A5=1))>0)*'Coûts'!$I$5:$I$60) | Q5: =L5*('Paramètres'!$C$26+'Paramètres'!$C$27) | R5: =L5-M5-N5-O5-P5-Q5 | S5: 0 | T5: =R5+S5
A6: 2 | B6: =EDATE('Paramètres'!$C$28,A6-1) | C6: =IF(A6<=12,"Année 1","Année 2") | D6: =IF(A6>='Paramètres'!$C$8,'Paramètres'!$C$9,0) | E6: =E5*(1-'Paramètres'!$C$10)+D6 | F6: =IF(A6>='Paramètres'!$C$13,'Paramètres'!$C$14,0) | G6: =G5*(1-'Paramètres'!$C$10)+F6 | H6: =IF(A6>='Paramètres'!$C$13,'Paramètres'!$C$15,0) | I6: =I5*(1-'Paramètres'!$C$10)+H6 | J6: =D6*'Paramètres'!$C$19+F6*'Paramètres'!$C$20+H6*'Paramètres'!$C$21 | K6: =E6*'Paramètres'!$D$19+G6*'Paramètres'!$D$20+I6*'Paramètres'!$D$21 | L6: =J6+K6 | M6: =E6*'Paramètres'!$C$11+G6*'Paramètres'!$E$20+I6*'Paramètres'!$E$21 | N6: =L6*'Paramètres'!$C$24+(D6+E6+F6+G6+H6+I6)*'Paramètres'!$C$25 | O6: =SUMPRODUCT(('Coûts'!$D$5:$D$60="Mensuel")*('Coûts'!$J$5:$J$60="Oui")*('Coûts'!$K$5:$K$60<=EOMONTH(B6,0))*(('Coûts'!$L$5:$L$60="")+('Coûts'!$L$5:$L$60>=B6)>0)*'Coûts'!$H$5:$H$60)+SUMPRODUCT(('Coûts'!$D$5:$D$60="Annuel")*('Coûts'!$J$5:$J$60="Oui")*('Coûts'!$K$5:$K$60<=EOMONTH(B6,0))*(('Coûts'!$L$5:$L$60="")+('Coûts'!$L$5:$L$60>=B6)>0)*'Coûts'!$H$5:$H$60)+'Paramètres'!$C$12 | P6: =SUMPRODUCT(('Coûts'!$D$5:$D$60="Ponctuel")*('Coûts'!$J$5:$J$60="Oui")*('Coûts'!$K$5:$K$60<=EOMONTH(B6,0))*((('Coûts'!$K$5:$K$60>=B6)+(A6=1))>0)*'Coûts'!$I$5:$I$60) | Q6: =L6*('Paramètres'!$C$26+'Paramètres'!$C$27) | R6: =L6-M6-N6-O6-P6-Q6 | S6: 0 | T6: =T5+R6+S6
A7: 3 | B7: =EDATE('Paramètres'!$C$28,A7-1) | C7: =IF(A7<=12,"Année 1","Année 2") | D7: =IF(A7>='Paramètres'!$C$8,'Paramètres'!$C$9,0) | E7: =E6*(1-'Paramètres'!$C$10)+D7 | F7: =IF(A7>='Paramètres'!$C$13,'Paramètres'!$C$14,0) | G7: =G6*(1-'Paramètres'!$C$10)+F7 | H7: =IF(A7>='Paramètres'!$C$13,'Paramètres'!$C$15,0) | I7: =I6*(1-'Paramètres'!$C$10)+H7 | J7: =D7*'Paramètres'!$C$19+F7*'Paramètres'!$C$20+H7*'Paramètres'!$C$21 | K7: =E7*'Paramètres'!$D$19+G7*'Paramètres'!$D$20+I7*'Paramètres'!$D$21 | L7: =J7+K7 | M7: =E7*'Paramètres'!$C$11+G7*'Paramètres'!$E$20+I7*'Paramètres'!$E$21 | N7: =L7*'Paramètres'!$C$24+(D7+E7+F7+G7+H7+I7)*'Paramètres'!$C$25 | O7: =SUMPRODUCT(('Coûts'!$D$5:$D$60="Mensuel")*('Coûts'!$J$5:$J$60="Oui")*('Coûts'!$K$5:$K$60<=EOMONTH(B7,0))*(('Coûts'!$L$5:$L$60="")+('Coûts'!$L$5:$L$60>=B7)>0)*'Coûts'!$H$5:$H$60)+SUMPRODUCT(('Coûts'!$D$5:$D$60="Annuel")*('Coûts'!$J$5:$J$60="Oui")*('Coûts'!$K$5:$K$60<=EOMONTH(B7,0))*(('Coûts'!$L$5:$L$60="")+('Coûts'!$L$5:$L$60>=B7)>0)*'Coûts'!$H$5:$H$60)+'Paramètres'!$C$12 | P7: =SUMPRODUCT(('Coûts'!$D$5:$D$60="Ponctuel")*('Coûts'!$J$5:$J$60="Oui")*('Coûts'!$K$5:$K$60<=EOMONTH(B7,0))*((('Coûts'!$K$5:$K$60>=B7)+(A7=1))>0)*'Coûts'!$I$5:$I$60) | Q7: =L7*('Paramètres'!$C$26+'Paramètres'!$C$27) | R7: =L7-M7-N7-O7-P7-Q7 | S7: 0 | T7: =T6+R7+S7
A8: 4 | B8: =EDATE('Paramètres'!$C$28,A8-1) | C8: =IF(A8<=12,"Année 1","Année 2") | D8: =IF(A8>='Paramètres'!$C$8,'Paramètres'!$C$9,0) | E8: =E7*(1-'Paramètres'!$C$10)+D8 | F8: =IF(A8>='Paramètres'!$C$13,'Paramètres'!$C$14,0) | G8: =G7*(1-'Paramètres'!$C$10)+F8 | H8: =IF(A8>='Paramètres'!$C$13,'Paramètres'!$C$15,0) | I8: =I7*(1-'Paramètres'!$C$10)+H8 | J8: =D8*'Paramètres'!$C$19+F8*'Paramètres'!$C$20+H8*'Paramètres'!$C$21 | K8: =E8*'Paramètres'!$D$19+G8*'Paramètres'!$D$20+I8*'Paramètres'!$D$21 | L8: =J8+K8 | M8: =E8*'Paramètres'!$C$11+G8*'Paramètres'!$E$20+I8*'Paramètres'!$E$21 | N8: =L8*'Paramètres'!$C$24+(D8+E8+F8+G8+H8+I8)*'Paramètres'!$C$25 | O8: =SUMPRODUCT(('Coûts'!$D$5:$D$60="Mensuel")*('Coûts'!$J$5:$J$60="Oui")*('Coûts'!$K$5:$K$60<=EOMONTH(B8,0))*(('Coûts'!$L$5:$L$60="")+('Coûts'!$L$5:$L$60>=B8)>0)*'Coûts'!$H$5:$H$60)+SUMPRODUCT(('Coûts'!$D$5:$D$60="Annuel")*('Coûts'!$J$5:$J$60="Oui")*('Coûts'!$K$5:$K$60<=EOMONTH(B8,0))*(('Coûts'!$L$5:$L$60="")+('Coûts'!$L$5:$L$60>=B8)>0)*'Coûts'!$H$5:$H$60)+'Paramètres'!$C$12 | P8: =SUMPRODUCT(('Coûts'!$D$5:$D$60="Ponctuel")*('Coûts'!$J$5:$J$60="Oui")*('Coûts'!$K$5:$K$60<=EOMONTH(B8,0))*((('Coûts'!$K$5:$K$60>=B8)+(A8=1))>0)*'Coûts'!$I$5:$I$60) | Q8: =L8*('Paramètres'!$C$26+'Paramètres'!$C$27) | R8: =L8-M8-N8-O8-P8-Q8 | S8: 0 | T8: =T7+R8+S8
A9: 5 | B9: =EDATE('Paramètres'!$C$28,A9-1) | C9: =IF(A9<=12,"Année 1","Année 2") | D9: =IF(A9>='Paramètres'!$C$8,'Paramètres'!$C$9,0) | E9: =E8*(1-'Paramètres'!$C$10)+D9 | F9: =IF(A9>='Paramètres'!$C$13,'Paramètres'!$C$14,0) | G9: =G8*(1-'Paramètres'!$C$10)+F9 | H9: =IF(A9>='Paramètres'!$C$13,'Paramètres'!$C$15,0) | I9: =I8*(1-'Paramètres'!$C$10)+H9 | J9: =D9*'Paramètres'!$C$19+F9*'Paramètres'!$C$20+H9*'Paramètres'!$C$21 | K9: =E9*'Paramètres'!$D$19+G9*'Paramètres'!$D$20+I9*'Paramètres'!$D$21 | L9: =J9+K9 | M9: =E9*'Paramètres'!$C$11+G9*'Paramètres'!$E$20+I9*'Paramètres'!$E$21 | N9: =L9*'Paramètres'!$C$24+(D9+E9+F9+G9+H9+I9)*'Paramètres'!$C$25 | O9: =SUMPRODUCT(('Coûts'!$D$5:$D$60="Mensuel")*('Coûts'!$J$5:$J$60="Oui")*('Coûts'!$K$5:$K$60<=EOMONTH(B9,0))*(('Coûts'!$L$5:$L$60="")+('Coûts'!$L$5:$L$60>=B9)>0)*'Coûts'!$H$5:$H$60)+SUMPRODUCT(('Coûts'!$D$5:$D$60="Annuel")*('Coûts'!$J$5:$J$60="Oui")*('Coûts'!$K$5:$K$60<=EOMONTH(B9,0))*(('Coûts'!$L$5:$L$60="")+('Coûts'!$L$5:$L$60>=B9)>0)*'Coûts'!$H$5:$H$60)+'Paramètres'!$C$12 | P9: =SUMPRODUCT(('Coûts'!$D$5:$D$60="Ponctuel")*('Coûts'!$J$5:$J$60="Oui")*('Coûts'!$K$5:$K$60<=EOMONTH(B9,0))*((('Coûts'!$K$5:$K$60>=B9)+(A9=1))>0)*'Coûts'!$I$5:$I$60) | Q9: =L9*('Paramètres'!$C$26+'Paramètres'!$C$27) | R9: =L9-M9-N9-O9-P9-Q9 | S9: 0 | T9: =T8+R9+S9
A10: 6 | B10: =EDATE('Paramètres'!$C$28,A10-1) | C10: =IF(A10<=12,"Année 1","Année 2") | D10: =IF(A10>='Paramètres'!$C$8,'Paramètres'!$C$9,0) | E10: =E9*(1-'Paramètres'!$C$10)+D10 | F10: =IF(A10>='Paramètres'!$C$13,'Paramètres'!$C$14,0) | G10: =G9*(1-'Paramètres'!$C$10)+F10 | H10: =IF(A10>='Paramètres'!$C$13,'Paramètres'!$C$15,0) | I10: =I9*(1-'Paramètres'!$C$10)+H10 | J10: =D10*'Paramètres'!$C$19+F10*'Paramètres'!$C$20+H10*'Paramètres'!$C$21 | K10: =E10*'Paramètres'!$D$19+G10*'Paramètres'!$D$20+I10*'Paramètres'!$D$21 | L10: =J10+K10 | M10: =E10*'Paramètres'!$C$11+G10*'Paramètres'!$E$20+I10*'Paramètres'!$E$21 | N10: =L10*'Paramètres'!$C$24+(D10+E10+F10+G10+H10+I10)*'Paramètres'!$C$25 | O10: =SUMPRODUCT(('Coûts'!$D$5:$D$60="Mensuel")*('Coûts'!$J$5:$J$60="Oui")*('Coûts'!$K$5:$K$60<=EOMONTH(B10,0))*(('Coûts'!$L$5:$L$60="")+('Coûts'!$L$5:$L$60>=B10)>0)*'Coûts'!$H$5:$H$60)+SUMPRODUCT(('Coûts'!$D$5:$D$60="Annuel")*('Coûts'!$J$5:$J$60="Oui")*('Coûts'!$K$5:$K$60<=EOMONTH(B10,0))*(('Coûts'!$L$5:$L$60="")+('Coûts'!$L$5:$L$60>=B10)>0)*'Coûts'!$H$5:$H$60)+'Paramètres'!$C$12 | P10: =SUMPRODUCT(('Coûts'!$D$5:$D$60="Ponctuel")*('Coûts'!$J$5:$J$60="Oui")*('Coûts'!$K$5:$K$60<=EOMONTH(B10,0))*((('Coûts'!$K$5:$K$60>=B10)+(A10=1))>0)*'Coûts'!$I$5:$I$60) | Q10: =L10*('Paramètres'!$C$26+'Paramètres'!$C$27) | R10: =L10-M10-N10-O10-P10-Q10 | S10: 0 | T10: =T9+R10+S10
A11: 7 | B11: =EDATE('Paramètres'!$C$28,A11-1) | C11: =IF(A11<=12,"Année 1","Année 2") | D11: =IF(A11>='Paramètres'!$C$8,'Paramètres'!$C$9,0) | E11: =E10*(1-'Paramètres'!$C$10)+D11 | F11: =IF(A11>='Paramètres'!$C$13,'Paramètres'!$C$14,0) | G11: =G10*(1-'Paramètres'!$C$10)+F11 | H11: =IF(A11>='Paramètres'!$C$13,'Paramètres'!$C$15,0) | I11: =I10*(1-'Paramètres'!$C$10)+H11 | J11: =D11*'Paramètres'!$C$19+F11*'Paramètres'!$C$20+H11*'Paramètres'!$C$21 | K11: =E11*'Paramètres'!$D$19+G11*'Paramètres'!$D$20+I11*'Paramètres'!$D$21 | L11: =J11+K11 | M11: =E11*'Paramètres'!$C$11+G11*'Paramètres'!$E$20+I11*'Paramètres'!$E$21 | N11: =L11*'Paramètres'!$C$24+(D11+E11+F11+G11+H11+I11)*'Paramètres'!$C$25 | O11: =SUMPRODUCT(('Coûts'!$D$5:$D$60="Mensuel")*('Coûts'!$J$5:$J$60="Oui")*('Coûts'!$K$5:$K$60<=EOMONTH(B11,0))*(('Coûts'!$L$5:$L$60="")+('Coûts'!$L$5:$L$60>=B11)>0)*'Coûts'!$H$5:$H$60)+SUMPRODUCT(('Coûts'!$D$5:$D$60="Annuel")*('Coûts'!$J$5:$J$60="Oui")*('Coûts'!$K$5:$K$60<=EOMONTH(B11,0))*(('Coûts'!$L$5:$L$60="")+('Coûts'!$L$5:$L$60>=B11)>0)*'Coûts'!$H$5:$H$60)+'Paramètres'!$C$12 | P11: =SUMPRODUCT(('Coûts'!$D$5:$D$60="Ponctuel")*('Coûts'!$J$5:$J$60="Oui")*('Coûts'!$K$5:$K$60<=EOMONTH(B11,0))*((('Coûts'!$K$5:$K$60>=B11)+(A11=1))>0)*'Coûts'!$I$5:$I$60) | Q11: =L11*('Paramètres'!$C$26+'Paramètres'!$C$27) | R11: =L11-M11-N11-O11-P11-Q11 | S11: 0 | T11: =T10+R11+S11
A12: 8 | B12: =EDATE('Paramètres'!$C$28,A12-1) | C12: =IF(A12<=12,"Année 1","Année 2") | D12: =IF(A12>='Paramètres'!$C$8,'Paramètres'!$C$9,0) | E12: =E11*(1-'Paramètres'!$C$10)+D12 | F12: =IF(A12>='Paramètres'!$C$13,'Paramètres'!$C$14,0) | G12: =G11*(1-'Paramètres'!$C$10)+F12 | H12: =IF(A12>='Paramètres'!$C$13,'Paramètres'!$C$15,0) | I12: =I11*(1-'Paramètres'!$C$10)+H12 | J12: =D12*'Paramètres'!$C$19+F12*'Paramètres'!$C$20+H12*'Paramètres'!$C$21 | K12: =E12*'Paramètres'!$D$19+G12*'Paramètres'!$D$20+I12*'Paramètres'!$D$21 | L12: =J12+K12 | M12: =E12*'Paramètres'!$C$11+G12*'Paramètres'!$E$20+I12*'Paramètres'!$E$21 | N12: =L12*'Paramètres'!$C$24+(D12+E12+F12+G12+H12+I12)*'Paramètres'!$C$25 | O12: =SUMPRODUCT(('Coûts'!$D$5:$D$60="Mensuel")*('Coûts'!$J$5:$J$60="Oui")*('Coûts'!$K$5:$K$60<=EOMONTH(B12,0))*(('Coûts'!$L$5:$L$60="")+('Coûts'!$L$5:$L$60>=B12)>0)*'Coûts'!$H$5:$H$60)+SUMPRODUCT(('Coûts'!$D$5:$D$60="Annuel")*('Coûts'!$J$5:$J$60="Oui")*('Coûts'!$K$5:$K$60<=EOMONTH(B12,0))*(('Coûts'!$L$5:$L$60="")+('Coûts'!$L$5:$L$60>=B12)>0)*'Coûts'!$H$5:$H$60)+'Paramètres'!$C$12 | P12: =SUMPRODUCT(('Coûts'!$D$5:$D$60="Ponctuel")*('Coûts'!$J$5:$J$60="Oui")*('Coûts'!$K$5:$K$60<=EOMONTH(B12,0))*((('Coûts'!$K$5:$K$60>=B12)+(A12=1))>0)*'Coûts'!$I$5:$I$60) | Q12: =L12*('Paramètres'!$C$26+'Paramètres'!$C$27) | R12: =L12-M12-N12-O12-P12-Q12 | S12: 0 | T12: =T11+R12+S12
A13: 9 | B13: =EDATE('Paramètres'!$C$28,A13-1) | C13: =IF(A13<=12,"Année 1","Année 2") | D13: =IF(A13>='Paramètres'!$C$8,'Paramètres'!$C$9,0) | E13: =E12*(1-'Paramètres'!$C$10)+D13 | F13: =IF(A13>='Paramètres'!$C$13,'Paramètres'!$C$14,0) | G13: =G12*(1-'Paramètres'!$C$10)+F13 | H13: =IF(A13>='Paramètres'!$C$13,'Paramètres'!$C$15,0) | I13: =I12*(1-'Paramètres'!$C$10)+H13 | J13: =D13*'Paramètres'!$C$19+F13*'Paramètres'!$C$20+H13*'Paramètres'!$C$21 | K13: =E13*'Paramètres'!$D$19+G13*'Paramètres'!$D$20+I13*'Paramètres'!$D$21 | L13: =J13+K13 | M13: =E13*'Paramètres'!$C$11+G13*'Paramètres'!$E$20+I13*'Paramètres'!$E$21 | N13: =L13*'Paramètres'!$C$24+(D13+E13+F13+G13+H13+I13)*'Paramètres'!$C$25 | O13: =SUMPRODUCT(('Coûts'!$D$5:$D$60="Mensuel")*('Coûts'!$J$5:$J$60="Oui")*('Coûts'!$K$5:$K$60<=EOMONTH(B13,0))*(('Coûts'!$L$5:$L$60="")+('Coûts'!$L$5:$L$60>=B13)>0)*'Coûts'!$H$5:$H$60)+SUMPRODUCT(('Coûts'!$D$5:$D$60="Annuel")*('Coûts'!$J$5:$J$60="Oui")*('Coûts'!$K$5:$K$60<=EOMONTH(B13,0))*(('Coûts'!$L$5:$L$60="")+('Coûts'!$L$5:$L$60>=B13)>0)*'Coûts'!$H$5:$H$60)+'Paramètres'!$C$12 | P13: =SUMPRODUCT(('Coûts'!$D$5:$D$60="Ponctuel")*('Coûts'!$J$5:$J$60="Oui")*('Coûts'!$K$5:$K$60<=EOMONTH(B13,0))*((('Coûts'!$K$5:$K$60>=B13)+(A13=1))>0)*'Coûts'!$I$5:$I$60) | Q13: =L13*('Paramètres'!$C$26+'Paramètres'!$C$27) | R13: =L13-M13-N13-O13-P13-Q13 | S13: 0 | T13: =T12+R13+S13
A14: 10 | B14: =EDATE('Paramètres'!$C$28,A14-1) | C14: =IF(A14<=12,"Année 1","Année 2") | D14: =IF(A14>='Paramètres'!$C$8,'Paramètres'!$C$9,0) | E14: =E13*(1-'Paramètres'!$C$10)+D14 | F14: =IF(A14>='Paramètres'!$C$13,'Paramètres'!$C$14,0) | G14: =G13*(1-'Paramètres'!$C$10)+F14 | H14: =IF(A14>='Paramètres'!$C$13,'Paramètres'!$C$15,0) | I14: =I13*(1-'Paramètres'!$C$10)+H14 | J14: =D14*'Paramètres'!$C$19+F14*'Paramètres'!$C$20+H14*'Paramètres'!$C$21 | K14: =E14*'Paramètres'!$D$19+G14*'Paramètres'!$D$20+I14*'Paramètres'!$D$21 | L14: =J14+K14 | M14: =E14*'Paramètres'!$C$11+G14*'Paramètres'!$E$20+I14*'Paramètres'!$E$21 | N14: =L14*'Paramètres'!$C$24+(D14+E14+F14+G14+H14+I14)*'Paramètres'!$C$25 | O14: =SUMPRODUCT(('Coûts'!$D$5:$D$60="Mensuel")*('Coûts'!$J$5:$J$60="Oui")*('Coûts'!$K$5:$K$60<=EOMONTH(B14,0))*(('Coûts'!$L$5:$L$60="")+('Coûts'!$L$5:$L$60>=B14)>0)*'Coûts'!$H$5:$H$60)+SUMPRODUCT(('Coûts'!$D$5:$D$60="Annuel")*('Coûts'!$J$5:$J$60="Oui")*('Coûts'!$K$5:$K$60<=EOMONTH(B14,0))*(('Coûts'!$L$5:$L$60="")+('Coûts'!$L$5:$L$60>=B14)>0)*'Coûts'!$H$5:$H$60)+'Paramètres'!$C$12 | P14: =SUMPRODUCT(('Coûts'!$D$5:$D$60="Ponctuel")*('Coûts'!$J$5:$J$60="Oui")*('Coûts'!$K$5:$K$60<=EOMONTH(B14,0))*((('Coûts'!$K$5:$K$60>=B14)+(A14=1))>0)*'Coûts'!$I$5:$I$60) | Q14: =L14*('Paramètres'!$C$26+'Paramètres'!$C$27) | R14: =L14-M14-N14-O14-P14-Q14 | S14: 0 | T14: =T13+R14+S14
A15: 11 | B15: =EDATE('Paramètres'!$C$28,A15-1) | C15: =IF(A15<=12,"Année 1","Année 2") | D15: =IF(A15>='Paramètres'!$C$8,'Paramètres'!$C$9,0) | E15: =E14*(1-'Paramètres'!$C$10)+D15 | F15: =IF(A15>='Paramètres'!$C$13,'Paramètres'!$C$14,0) | G15: =G14*(1-'Paramètres'!$C$10)+F15 | H15: =IF(A15>='Paramètres'!$C$13,'Paramètres'!$C$15,0) | I15: =I14*(1-'Paramètres'!$C$10)+H15 | J15: =D15*'Paramètres'!$C$19+F15*'Paramètres'!$C$20+H15*'Paramètres'!$C$21 | K15: =E15*'Paramètres'!$D$19+G15*'Paramètres'!$D$20+I15*'Paramètres'!$D$21 | L15: =J15+K15 | M15: =E15*'Paramètres'!$C$11+G15*'Paramètres'!$E$20+I15*'Paramètres'!$E$21 | N15: =L15*'Paramètres'!$C$24+(D15+E15+F15+G15+H15+I15)*'Paramètres'!$C$25 | O15: =SUMPRODUCT(('Coûts'!$D$5:$D$60="Mensuel")*('Coûts'!$J$5:$J$60="Oui")*('Coûts'!$K$5:$K$60<=EOMONTH(B15,0))*(('Coûts'!$L$5:$L$60="")+('Coûts'!$L$5:$L$60>=B15)>0)*'Coûts'!$H$5:$H$60)+SUMPRODUCT(('Coûts'!$D$5:$D$60="Annuel")*('Coûts'!$J$5:$J$60="Oui")*('Coûts'!$K$5:$K$60<=EOMONTH(B15,0))*(('Coûts'!$L$5:$L$60="")+('Coûts'!$L$5:$L$60>=B15)>0)*'Coûts'!$H$5:$H$60)+'Paramètres'!$C$12 | P15: =SUMPRODUCT(('Coûts'!$D$5:$D$60="Ponctuel")*('Coûts'!$J$5:$J$60="Oui")*('Coûts'!$K$5:$K$60<=EOMONTH(B15,0))*((('Coûts'!$K$5:$K$60>=B15)+(A15=1))>0)*'Coûts'!$I$5:$I$60) | Q15: =L15*('Paramètres'!$C$26+'Paramètres'!$C$27) | R15: =L15-M15-N15-O15-P15-Q15 | S15: 0 | T15: =T14+R15+S15
A16: 12 | B16: =EDATE('Paramètres'!$C$28,A16-1) | C16: =IF(A16<=12,"Année 1","Année 2") | D16: =IF(A16>='Paramètres'!$C$8,'Paramètres'!$C$9,0) | E16: =E15*(1-'Paramètres'!$C$10)+D16 | F16: =IF(A16>='Paramètres'!$C$13,'Paramètres'!$C$14,0) | G16: =G15*(1-'Paramètres'!$C$10)+F16 | H16: =IF(A16>='Paramètres'!$C$13,'Paramètres'!$C$15,0) | I16: =I15*(1-'Paramètres'!$C$10)+H16 | J16: =D16*'Paramètres'!$C$19+F16*'Paramètres'!$C$20+H16*'Paramètres'!$C$21 | K16: =E16*'Paramètres'!$D$19+G16*'Paramètres'!$D$20+I16*'Paramètres'!$D$21 | L16: =J16+K16 | M16: =E16*'Paramètres'!$C$11+G16*'Paramètres'!$E$20+I16*'Paramètres'!$E$21 | N16: =L16*'Paramètres'!$C$24+(D16+E16+F16+G16+H16+I16)*'Paramètres'!$C$25 | O16: =SUMPRODUCT(('Coûts'!$D$5:$D$60="Mensuel")*('Coûts'!$J$5:$J$60="Oui")*('Coûts'!$K$5:$K$60<=EOMONTH(B16,0))*(('Coûts'!$L$5:$L$60="")+('Coûts'!$L$5:$L$60>=B16)>0)*'Coûts'!$H$5:$H$60)+SUMPRODUCT(('Coûts'!$D$5:$D$60="Annuel")*('Coûts'!$J$5:$J$60="Oui")*('Coûts'!$K$5:$K$60<=EOMONTH(B16,0))*(('Coûts'!$L$5:$L$60="")+('Coûts'!$L$5:$L$60>=B16)>0)*'Coûts'!$H$5:$H$60)+'Paramètres'!$C$12 | P16: =SUMPRODUCT(('Coûts'!$D$5:$D$60="Ponctuel")*('Coûts'!$J$5:$J$60="Oui")*('Coûts'!$K$5:$K$60<=EOMONTH(B16,0))*((('Coûts'!$K$5:$K$60>=B16)+(A16=1))>0)*'Coûts'!$I$5:$I$60) | Q16: =L16*('Paramètres'!$C$26+'Paramètres'!$C$27) | R16: =L16-M16-N16-O16-P16-Q16 | S16: 0 | T16: =T15+R16+S16
A17: 13 | B17: =EDATE('Paramètres'!$C$28,A17-1) | C17: =IF(A17<=12,"Année 1","Année 2") | D17: =IF(A17>='Paramètres'!$C$8,'Paramètres'!$C$9,0) | E17: =E16*(1-'Paramètres'!$C$10)+D17 | F17: =IF(A17>='Paramètres'!$C$13,'Paramètres'!$C$14,0) | G17: =G16*(1-'Paramètres'!$C$10)+F17 | H17: =IF(A17>='Paramètres'!$C$13,'Paramètres'!$C$15,0) | I17: =I16*(1-'Paramètres'!$C$10)+H17 | J17: =D17*'Paramètres'!$C$19+F17*'Paramètres'!$C$20+H17*'Paramètres'!$C$21 | K17: =E17*'Paramètres'!$D$19+G17*'Paramètres'!$D$20+I17*'Paramètres'!$D$21 | L17: =J17+K17 | M17: =E17*'Paramètres'!$C$11+G17*'Paramètres'!$E$20+I17*'Paramètres'!$E$21 | N17: =L17*'Paramètres'!$C$24+(D17+E17+F17+G17+H17+I17)*'Paramètres'!$C$25 | O17: =SUMPRODUCT(('Coûts'!$D$5:$D$60="Mensuel")*('Coûts'!$J$5:$J$60="Oui")*('Coûts'!$K$5:$K$60<=EOMONTH(B17,0))*(('Coûts'!$L$5:$L$60="")+('Coûts'!$L$5:$L$60>=B17)>0)*'Coûts'!$H$5:$H$60)+SUMPRODUCT(('Coûts'!$D$5:$D$60="Annuel")*('Coûts'!$J$5:$J$60="Oui")*('Coûts'!$K$5:$K$60<=EOMONTH(B17,0))*(('Coûts'!$L$5:$L$60="")+('Coûts'!$L$5:$L$60>=B17)>0)*'Coûts'!$H$5:$H$60)+'Paramètres'!$C$12 | P17: =SUMPRODUCT(('Coûts'!$D$5:$D$60="Ponctuel")*('Coûts'!$J$5:$J$60="Oui")*('Coûts'!$K$5:$K$60<=EOMONTH(B17,0))*((('Coûts'!$K$5:$K$60>=B17)+(A17=1))>0)*'Coûts'!$I$5:$I$60) | Q17: =L17*('Paramètres'!$C$26+'Paramètres'!$C$27) | R17: =L17-M17-N17-O17-P17-Q17 | S17: 0 | T17: =T16+R17+S17
... A28: 24 | B28: =EDATE('Paramètres'!$C$28,A28-1) | C28: =IF(A28<=12,"Année 1","Année 2") | D28: =IF(A28>='Paramètres'!$C$8,'Paramètres'!$C$9,0) | E28: =E27*(1-'Paramètres'!$C$10)+D28 | F28: =IF(A28>='Paramètres'!$C$13,'Paramètres'!$C$14,0) | G28: =G27*(1-'Paramètres'!$C$10)+F28 | H28: =IF(A28>='Paramètres'!$C$13,'Paramètres'!$C$15,0) | I28: =I27*(1-'Paramètres'!$C$10)+H28 | J28: =D28*'Paramètres'!$C$19+F28*'Paramètres'!$C$20+H28*'Paramètres'!$C$21 | K28: =E28*'Paramètres'!$D$19+G28*'Paramètres'!$D$20+I28*'Paramètres'!$D$21 | L28: =J28+K28 | M28: =E28*'Paramètres'!$C$11+G28*'Paramètres'!$E$20+I28*'Paramètres'!$E$21 | N28: =L28*'Paramètres'!$C$24+(D28+E28+F28+G28+H28+I28)*'Paramètres'!$C$25 | O28: =SUMPRODUCT(('Coûts'!$D$5:$D$60="Mensuel")*('Coûts'!$J$5:$J$60="Oui")*('Coûts'!$K$5:$K$60<=EOMONTH(B28,0))*(('Coûts'!$L$5:$L$60="")+('Coûts'!$L$5:$L$60>=B28)>0)*'Coûts'!$H$5:$H$60)+SUMPRODUCT(('Coûts'!$D$5:$D$60="Annuel")*('Coûts'!$J$5:$J$60="Oui")*('Coûts'!$K$5:$K$60<=EOMONTH(B28,0))*(('Coûts'!$L$5:$L$60="")+('Coûts'!$L$5:$L$60>=B28)>0)*'Coûts'!$H$5:$H$60)+'Paramètres'!$C$12 | P28: =SUMPRODUCT(('Coûts'!$D$5:$D$60="Ponctuel")*('Coûts'!$J$5:$J$60="Oui")*('Coûts'!$K$5:$K$60<=EOMONTH(B28,0))*((('Coûts'!$K$5:$K$60>=B28)+(A28=1))>0)*'Coûts'!$I$5:$I$60) | Q28: =L28*('Paramètres'!$C$26+'Paramètres'!$C$27) | R28: =L28-M28-N28-O28-P28-Q28 | S28: 0 | T28: =T27+R28+S28
B29: Total | J29: =SUM(J5:J28) | K29: =SUM(K5:K28) | L29: =SUM(L5:L28) | M29: =SUM(M5:M28) | N29: =SUM(N5:N28) | O29: =SUM(O5:O28) | P29: =SUM(P5:P28) | Q29: =SUM(Q5:Q28) | ... S29: =SUM(S5:S28)

Sheet Bilan
B1: Compte de résultat et bilan simplifiés
B2: Vue de gestion issue de la projection (une micro-entreprise n'établit pas de bilan comptable).
B4: Compte de résultat | C4: Année 1 | D4: Année 2 | E4: Remarque
B5: Produits : chiffre d'affaires | C5: ='Synthèse'!C7 | D5: ='Synthèse'!D7
B6: Charges : coûts variables | C6: ='Synthèse'!C8 | D6: ='Synthèse'!D8 | E6: IA par client
B7: Charges : frais Stripe | C7: ='Synthèse'!C9 | D7: ='Synthèse'!D9
B8: Charges : frais fixes | C8: ='Synthèse'!C10 | D8: ='Synthèse'!D10 | E8: Hébergement, domaines, abonnements, assurance…
B9: Charges : dépenses ponctuelles | C9: ='Synthèse'!C11 | D9: ='Synthèse'!D11 | E9: Démarches, juridique, INPI, kit
B10: Charges : cotisations et impôt | C10: ='Synthèse'!C12 | D10: ='Synthèse'!D12
B11: Résultat de l'exercice | C11: =C5-SUM(C6:C10) | D11: =D5-SUM(D6:D10)
B14: Bilan au 30 septembre | C14: 2027 (fin année 1) | D14: 2028 (fin année 2) | E14: Remarque
B15: ACTIF
B16: Trésorerie disponible | C16: =MAX(0,'Projection'!T16) | D16: =MAX(0,'Projection'!T28) | E16: Compte bancaire
B17: Créances clients | C17: 0 | D17: 0 | E17: À saisir si factures non encaissées
B18: Total actif | C18: =SUM(C16:C17) | D18: =SUM(D16:D17)
B19: PASSIF
B20: Apports des associés (cumul) | C20: =SUM('Projection'!S5:S16) | D20: =SUM('Projection'!S5:S28) | E20: Capital ou compte courant d'associé
B21: Résultats cumulés | C21: =SUM('Projection'!R5:R16) | D21: =SUM('Projection'!R5:R28) | E21: Non distribués
B22: Besoin de financement non couvert | C22: =MAX(0,-'Projection'!T16) | D22: =MAX(0,-'Projection'!T28) | E22: Si > 0 : prévoir des apports dans Projection
B23: Total passif | C23: =SUM(C20:C22) | D23: =SUM(D20:D22)
B24: Contrôle (actif − passif = 0) | C24: =C18-C23 | D24: =D18-D23
B26: Créances clients saisies à l'actif : ajouter le même montant en résultat pour garder l'équilibre.

Sheet Avances
A1: Avances des associés (dépenses payées personnellement)
A2: À la création de la structure, le total non remboursé devient un compte courant d'associé.
A4: Date | B4: Dépense | C4: Montant | D4: Devise | E4: Montant (€) | F4: Avancé par | G4: Remboursé le | H4: Statut | I4: Remarque | K4: Synthèse | L4: €
A5: 46291 | B5: Domaine ai-team.fr | D5: € | E5: =IF(C5="","",IF(D5="$",C5*'Paramètres'!$C$5,C5)) | F5: Daouda | H5: =IF(B5="","",IF(G5="","À rembourser","Remboursé")) | I5: Montant à renseigner | K5: Avancé par Daouda | L5: =SUMIFS(E5:E80,F5:F80,"Daouda")
A6: 46291 | B6: Domaine ia-factor.fr (1re année) | C6: 12.99 | D6: $ | E6: =IF(C6="","",IF(D6="$",C6*'Paramètres'!$C$5,C6)) | F6: Daouda | H6: =IF(B6="","",IF(G6="","À rembourser","Remboursé")) | I6: Vérifier sur la facture | K6: Avancé par Régis | L6: =SUMIFS(E5:E80,F5:F80,"Régis")
A7: 46291 | B7: VPS KVM 2 (1re période) | C7: 24.49 | D7: $ | E7: =IF(C7="","",IF(D7="$",C7*'Paramètres'!$C$5,C7)) | F7: Daouda | H7: =IF(B7="","",IF(G7="","À rembourser","Remboursé")) | I7: Vérifier sur la facture hPanel | K7: Total avancé | L7: =L5+L6
A8: 46291 | B8: Domaine ia-factor.com | C8: 10 | D8: € | E8: =IF(C8="","",IF(D8="$",C8*'Paramètres'!$C$5,C8)) | F8: Régis | H8: =IF(B8="","",IF(G8="","À rembourser","Remboursé")) | K8: Reste à rembourser à Daouda | L8: =SUMIFS(E5:E80,F5:F80,"Daouda",G5:G80,"")
A9: 46292 | B9: Crédits API Claude | C9: 6 | D9: $ | E9: =IF(C9="","",IF(D9="$",C9*'Paramètres'!$C$5,C9)) | F9: Daouda | H9: =IF(B9="","",IF(G9="","À rembourser","Remboursé")) | I9: Expirent le 27/09/2027 | K9: Reste à rembourser à Régis | L9: =SUMIFS(E5:E80,F5:F80,"Régis",G5:G80,"")
E10: =IF(C10="","",IF(D10="$",C10*'Paramètres'!$C$5,C10)) | H10: =IF(B10="","",IF(G10="","À rembourser","Remboursé")) | K10: Écart à 50/50 (positif : Régis doit à Daouda) | L10: =(L5-L6)/2
E11: =IF(C11="","",IF(D11="$",C11*'Paramètres'!$C$5,C11)) | H11: =IF(B11="","",IF(G11="","À rembourser","Remboursé"))
E12: =IF(C12="","",IF(D12="$",C12*'Paramètres'!$C$5,C12)) | H12: =IF(B12="","",IF(G12="","À rembourser","Remboursé"))
E13: =IF(C13="","",IF(D13="$",C13*'Paramètres'!$C$5,C13)) | H13: =IF(B13="","",IF(G13="","À rembourser","Remboursé"))
E14: =IF(C14="","",IF(D14="$",C14*'Paramètres'!$C$5,C14)) | H14: =IF(B14="","",IF(G14="","À rembourser","Remboursé"))
E15: =IF(C15="","",IF(D15="$",C15*'Paramètres'!$C$5,C15)) | H15: =IF(B15="","",IF(G15="","À rembourser","Remboursé"))
E16: =IF(C16="","",IF(D16="$",C16*'Paramètres'!$C$5,C16)) | H16: =IF(B16="","",IF(G16="","À rembourser","Remboursé"))
E17: =IF(C17="","",IF(D17="$",C17*'Paramètres'!$C$5,C17)) | H17: =IF(B17="","",IF(G17="","À rembourser","Remboursé"))
E18: =IF(C18="","",IF(D18="$",C18*'Paramètres'!$C$5,C18)) | H18: =IF(B18="","",IF(G18="","À rembourser","Remboursé"))
E19: =IF(C19="","",IF(D19="$",C19*'Paramètres'!$C$5,C19)) | H19: =IF(B19="","",IF(G19="","À rembourser","Remboursé"))
E20: =IF(C20="","",IF(D20="$",C20*'Paramètres'!$C$5,C20)) | H20: =IF(B20="","",IF(G20="","À rembourser","Remboursé"))
E21: =IF(C21="","",IF(D21="$",C21*'Paramètres'!$C$5,C21)) | H21: =IF(B21="","",IF(G21="","À rembourser","Remboursé"))
E22: =IF(C22="","",IF(D22="$",C22*'Paramètres'!$C$5,C22)) | H22: =IF(B22="","",IF(G22="","À rembourser","Remboursé"))
... E80: =IF(C80="","",IF(D80="$",C80*'Paramètres'!$C$5,C80)) | H80: =IF(B80="","",IF(G80="","À rembourser","Remboursé"))

Sheet Suivi réel
A1: Suivi réel mensuel
A2: Chaque début de mois : saisir le réel du mois écoulé (factures, relevé bancaire, Stripe, Console Anthropic).
A4: Mois | B4: Clients actifs réels | C4: Clients prévus | D4: CA réel | E4: CA prévu | F4: Charges réelles | G4: Charges prévues | H4: Résultat réel | I4: Résultat prévu | J4: Écart de résultat | K4: Commentaire
A5: ='Projection'!B5 | C5: ='Projection'!E5 | E5: ='Projection'!L5 | G5: ='Projection'!L5-'Projection'!R5 | H5: =IF(AND(D5="",F5=""),"",D5-F5) | I5: ='Projection'!R5 | J5: =IF(H5="","",H5-I5)
A6: ='Projection'!B6 | C6: ='Projection'!E6 | E6: ='Projection'!L6 | G6: ='Projection'!L6-'Projection'!R6 | H6: =IF(AND(D6="",F6=""),"",D6-F6) | I6: ='Projection'!R6 | J6: =IF(H6="","",H6-I6)
A7: ='Projection'!B7 | C7: ='Projection'!E7 | E7: ='Projection'!L7 | G7: ='Projection'!L7-'Projection'!R7 | H7: =IF(AND(D7="",F7=""),"",D7-F7) | I7: ='Projection'!R7 | J7: =IF(H7="","",H7-I7)
A8: ='Projection'!B8 | C8: ='Projection'!E8 | E8: ='Projection'!L8 | G8: ='Projection'!L8-'Projection'!R8 | H8: =IF(AND(D8="",F8=""),"",D8-F8) | I8: ='Projection'!R8 | J8: =IF(H8="","",H8-I8)
A9: ='Projection'!B9 | C9: ='Projection'!E9 | E9: ='Projection'!L9 | G9: ='Projection'!L9-'Projection'!R9 | H9: =IF(AND(D9="",F9=""),"",D9-F9) | I9: ='Projection'!R9 | J9: =IF(H9="","",H9-I9)
A10: ='Projection'!B10 | C10: ='Projection'!E10 | E10: ='Projection'!L10 | G10: ='Projection'!L10-'Projection'!R10 | H10: =IF(AND(D10="",F10=""),"",D10-F10) | I10: ='Projection'!R10 | J10: =IF(H10="","",H10-I10)
A11: ='Projection'!B11 | C11: ='Projection'!E11 | E11: ='Projection'!L11 | G11: ='Projection'!L11-'Projection'!R11 | H11: =IF(AND(D11="",F11=""),"",D11-F11) | I11: ='Projection'!R11 | J11: =IF(H11="","",H11-I11)
A12: ='Projection'!B12 | C12: ='Projection'!E12 | E12: ='Projection'!L12 | G12: ='Projection'!L12-'Projection'!R12 | H12: =IF(AND(D12="",F12=""),"",D12-F12) | I12: ='Projection'!R12 | J12: =IF(H12="","",H12-I12)
A13: ='Projection'!B13 | C13: ='Projection'!E13 | E13: ='Projection'!L13 | G13: ='Projection'!L13-'Projection'!R13 | H13: =IF(AND(D13="",F13=""),"",D13-F13) | I13: ='Projection'!R13 | J13: =IF(H13="","",H13-I13)
A14: ='Projection'!B14 | C14: ='Projection'!E14 | E14: ='Projection'!L14 | G14: ='Projection'!L14-'Projection'!R14 | H14: =IF(AND(D14="",F14=""),"",D14-F14) | I14: ='Projection'!R14 | J14: =IF(H14="","",H14-I14)
A15: ='Projection'!B15 | C15: ='Projection'!E15 | E15: ='Projection'!L15 | G15: ='Projection'!L15-'Projection'!R15 | H15: =IF(AND(D15="",F15=""),"",D15-F15) | I15: ='Projection'!R15 | J15: =IF(H15="","",H15-I15)
A16: ='Projection'!B16 | C16: ='Projection'!E16 | E16: ='Projection'!L16 | G16: ='Projection'!L16-'Projection'!R16 | H16: =IF(AND(D16="",F16=""),"",D16-F16) | I16: ='Projection'!R16 | J16: =IF(H16="","",H16-I16)
... A28: ='Projection'!B28 | C28: ='Projection'!E28 | E28: ='Projection'!L28 | G28: ='Projection'!L28-'Projection'!R28 | H28: =IF(AND(D28="",F28=""),"",D28-F28) | I28: ='Projection'!R28 | J28: =IF(H28="","",H28-I28)
